Workbook

Sheet Game States
A1: Parameter | B1: Value | C1: Code (BattleRules / file) | D1: Notes
A2: Floors per Run | B2: 3 | C2: FloorsPerRun | D2: ชนะบอสชั้น 3 = ชนะทั้งรัน
A3: Stages per Floor (min) | B3: 7 | C3: RunState.StagesThisFloor | D3: สุ่ม 7–10 ด่านต่อชั้น ด่านสุดท้ายคือบอส
A4: Stages per Floor (max) | B4: 10 | C4: RunState.StagesThisFloor
A5: Rounds per Duel | B5: 3 | C5: MaxRounds | D5: ครบ 3 รอบ ฝ่ายที่ดันเส้นนำอยู่ชนะ
A6: Beats per Phrase | B6: 8 | C6: BeatsPerRound | D6: TACET เล่นท่อนละ 8 บีต (ท่า 4/4 สองห้อง)
A7: Passes in Round 1 | B7: 1 | C7: PassesPerRound[0] | D7: REPEATS : รอบ 1 เล่นท่อน 1 ครั้ง
A8: Passes in Round 2 | B8: 2 | C8: PassesPerRound[1] | D8: รอบ 2 เล่นต่อกัน 2 ครั้ง
A9: Passes in Round 3 | B9: 3 | C9: PassesPerRound[2] | D9: รอบ 3 เล่นต่อกัน 3 ครั้ง
A10: Beats in a Full Duel | B10: =B6*(B7+B8+B9) | C10: (คำนวณ) | D10: บีตต่อท่อน × (1 + 2 + 3) ถ้าไม่มีใครชนะก่อน
A11: Line to Win (push) | B11: 100 | C11: LineLimit | D11: ดันเส้นถึง +100 ชนะทันที · ถูกดันถึง −100 แพ้
A12: Seats on Stage at Start | B12: 3 | C12: RunState.Seats | D12: ซื้อเพิ่มที่ร้านได้ (สูงสุด 9 ที่)
A13: Bench Size | B13: 3 | C13: BenchSize | D13: นักดนตรีที่นั่งพักได้ (ไม่ขึ้นเวที)
A14: Recruits at First Floor | B14: 3 | C14: FirstFloorRecruits | D14: คนที่ได้ตอนเปิดชั้น 1
A15: Recruits at Later Floors | B15: 1 | C15: LaterFloorRecruits
A16: Breath Back After a Win | B16: 0.3 | C16: RecoverAfterWin | D16: ได้ลมคืน 30% ของลมสูงสุด
A17: Signature Length (strokes) | B17: 4 | C17: SignatureStrokes | D17: SIGNATURE (Space) ทำงาน 4 ตวัด
A18: Round Banner (seconds) | B18: 1.1 | C18: IntroTime | D18: ป้าย ROUND ตอนเริ่มรอบ
A19: Round Change Note (seconds) | B19: 2.2 | C19: IntroNoteTime | D19: ป้ายบอกสิ่งที่เปลี่ยนในรอบนี้
A20: First Trait Card (seconds) | B20: 3.6 | C20: TraitIntroTime | D20: การ์ดอธิบายกลไกศัตรูครั้งแรก
A21: Teach Note (seconds) | B21: 3 | C21: TeachNoteTime | D21: ป้ายสอนของใหม่ครั้งแรกในรันจริง
A22: Round End (seconds) | B22: 1.4 | C22: RoundEndTime
A23: Signature Cut-in (seconds) | B23: 1 | C23: CutInTime | D23: ภาพ cut-in ตอนกด SIGNATURE (นาฬิกาจังหวะหยุด)

Sheet Entity Tuning
A1: Entity Tuning — TACET 4'33
A3: Player Setting (Conductor Base)
A4: Parameter | B4: Value | C4: Code | D4: Notes
A5: Breath Base | B5: 60 | C5: StaminaBase | D5: ลม (เลือดของวง) = ฐาน + 8 × ค่า BREATH บนการ์ด
A6: Breath per Stat Point | B6: 8 | C6: StaminaPerPoint
A7: Power Base | B7: 0.8 | C7: PowerBase | D7: ตัวคูณแรงทั้งวง = ฐาน + 0.04 × ค่า PUSH
A8: Power per Stat Point | B8: 0.04 | C8: PowerPerPoint
A10: Conductors (ผู้เล่นเลือก 1 คน)
A11: Max Breath / Power × คำนวณจากค่าด้านบน · Recipe = จำนวนโน้ต PERFECT ของแต่ละกลุ่มเครื่องที่ต้องเก็บก่อนกด SIGNATURE · ตัวเลขของ PASSIVE / SIGNATURE อยู่แท็บ Skill Damage
A12: Conductor | B12: Role | C12: Based On | D12: Breath Stat | E12: Push Stat | F12: Max Breath | G12: Power × | H12: Recipe STR | I12: Recipe WND | J12: Recipe PRC | K12: Passive | L12: Signature
A13: THE APPRENTICE | B13: BALANCED | C13: ORIGINAL CHARACTER | D13: 5 | E13: 5 | F13: ='Entity Tuning'!$B$5+D13*'Entity Tuning'!$B$6 | G13: ='Entity Tuning'!$B$7+E13*'Entity Tuning'!$B$8 | H13: 2 | I13: 2 | J13: 2 | K13: BY THE BOOK | L13: ABSOLUTE PITCH
A14: THE METRONOME | B14: ENDURANCE | C14: J. S. BACH | D14: 5 | E14: 6 | F14: ='Entity Tuning'!$B$5+D14*'Entity Tuning'!$B$6 | G14: ='Entity Tuning'!$B$7+E14*'Entity Tuning'!$B$8 | H14: 3 | I14: 0 | J14: 3 | K14: LOCKED TEMPO | L14: CLOCKWORK
A15: THE INFERNO | B15: BURST | C15: HECTOR BERLIOZ | D15: 3 | E15: 7 | F15: ='Entity Tuning'!$B$5+D15*'Entity Tuning'!$B$6 | G15: ='Entity Tuning'!$B$7+E15*'Entity Tuning'!$B$8 | H15: 2 | I15: 0 | J15: 3 | K15: RUNAWAY FIRE | L15: SET ALIGHT
A16: THE UNHEARING | B16: SCALING | C16: L. V. BEETHOVEN | D16: 5 | E16: 3 | F16: ='Entity Tuning'!$B$5+D16*'Entity Tuning'!$B$6 | G16: ='Entity Tuning'!$B$7+E16*'Entity Tuning'!$B$8 | H16: 3 | I16: 3 | J16: 0 | K16: THE CLOSER THE LOUDER | L16: DEAF EARS
A17: THE FOLK LEADER | B17: SUPPORT | C17: BELA BARTOK | D17: 5 | E17: 5 | F17: ='Entity Tuning'!$B$5+D17*'Entity Tuning'!$B$6 | G17: ='Entity Tuning'!$B$7+E17*'Entity Tuning'!$B$8 | H17: 3 | I17: 3 | J17: 3 | K17: EVERY ROAD HOME | L17: VILLAGE BAND
A19: Band (Musicians)
A20: Power = แรงต่อโน้ตบนการ์ด (ทุกคนบนเวทีเล่นทุกโน้ตที่ตวัดโดน) · Side = ฝั่งที่นั่งในวงจริง = ลูกศร CUE · ตัวเลขของความสามารถอยู่แท็บ Skill Damage
A21: Musician | B21: Instrument | C21: Family | D21: Era | E21: Side (CUE) | F21: Power | G21: Culture | H21: Trait
A22: ANNA | B22: VIOLIN | C22: STRINGS | D22: CLASSICAL | E22: LEFT | F22: 5 | G22: EUROPEAN | H22: COUNTS ALOUD
A23: KLARA | B23: FLUTE | C23: WINDS | D23: CLASSICAL | E23: CENTRE | F23: 4 | G23: EUROPEAN | H23: THE QUIET PART
A24: OTTO | B24: TIMPANI | C24: PERCUSSION | D24: CLASSICAL | E24: RIGHT | F24: 6 | G24: EUROPEAN | H24: MOMENTUM
A25: MALI | B25: SO DUANG | C25: STRINGS | D25: SIAM | E25: CENTRE | F25: 5 | G25: SIAM | H25: BY EAR
A26: CHAI | B26: PI NAI | C26: WINDS | D26: SIAM | E26: RIGHT | F26: 4 | G26: SIAM | H26: HELD NOTE
A27: NUAN | B27: RANAT EK | C27: PERCUSSION | D27: SIAM | E27: LEFT | F27: 6 | G27: SIAM | H27: ONE STEP BETTER
A28: LUKA | B28: CELLO | C28: STRINGS | D28: ROMANTIC | E28: RIGHT | F28: 6 | G28: EUROPEAN | H28: FOUR BARS STRAIGHT
A29: IRIS | B29: HORN | C29: WINDS | D29: ROMANTIC | E29: LEFT | F29: 5 | G29: EUROPEAN | H29: FASHIONABLY LATE
A30: BORIS | B30: BASS DRUM | C30: PERCUSSION | D30: ROMANTIC | E30: CENTRE | F30: 7 | G30: EUROPEAN | H30: THE WHOLE FLOOR
A31: Average Power (9 คน) | F31: =AVERAGE(F22:F30)
A33: Enemy Scaling
A34: แรงโน้ตของศัตรู = แรงฐานต่อโน้ต × แรงตามชั้น × ตัวคูณชนิดศัตรู (BattleState) · โน้ต f ×2 · โน้ต p ×0.5 (แท็บ Skill Damage)
A35: Parameter | B35: Value | C35: Code | D35: Notes
A36: Normal Enemy Scale | B36: 3.4 | C36: NormalScale | D36: ศัตรูข้างทาง
A37: Elite Enemy Scale | B37: 2.1 | C37: EliteScale
A38: Boss Enemy Scale | B38: 2.7 | C38: BossScale
A40: Floor Power | B40: Floor 1 | C40: Floor 2 | D40: Floor 3
A41: NORMAL | B41: 0.8 | C41: 1.25 | D41: 2.1
A42: MAESTRO | B42: 1 | C42: 1.65 | D42: 2.4
A44: Enemy Settings
A45: B1–B8 (ขวาสุด) = Pattern ต่อบีต (0 = เงียบ) · ศัตรูที่มีเพลงใช้ค่าเฉลี่ยของ Pattern เป็นแรงทุกโน้ต · THE DEVIL'S STRING ไม่มีเพลง เล่นตาม Pattern ทีละบีต ตารางนี้ใช้บีตที่แรงสุด (9) · แรงต่อชั้นปัด .5 ไปเลขคู่แบบเดียวกับเกม (C# Math.Round) · Push to Win = เส้นที่ต้องดันจริงเมื่อเส้นหนัก (HEAVY LINE)
A46: Enemy | B46: Kind | C46: Song | D46: Base Note | E46: Kind Scale | F46: NORMAL F1 | G46: NORMAL F2 | H46: NORMAL F3 | I46: MAESTRO F1 | J46: MAESTRO F2 | K46: MAESTRO F3 | L46: Line Weight | M46: Push to Win | N46: Trait (from floor) | O46: B1 | P46: B2 | Q46: B3 | R46: B4 | S46: B5 | T46: B6 | U46: B7 | V46: B8
...

Sheet Skill Damage
A1: Duel Multipliers
A2: Parameter | B2: Value | C2: Applies To | D2: Code | E2: Notes
A3: CUE (arrow matches baton) | B3: 1.5 | C3: BAND | D3: CuePower | E3: คนที่ลูกศรตรงทิศที่ไม้ตวัด แรง ×1.5
A4: Harmony per Extra Player | B4: 0.15 | C4: BAND | D4: HarmonyPerExtra | E4: เล่นพร้อมกันหลายคน แรงขึ้นคนละ 15%
A5: Harmony Counts Up To (players) | B5: 5 | C5: BAND | D5: HarmonyMost | E5: คนที่ 6 ขึ้นไปเพิ่มพลังแต่ไม่เพิ่มฮาร์โมนี
A6: SECTION : 2 of a family | B6: 0.1 | C6: BAND | D6: SectionTwo | E6: เครื่องกลุ่มเดียวกันบนเวที 2 คน
A7: SECTION : all 3 of a family | B7: 0.25 | C7: BAND | D7: SectionThree
A8: COMBO per PERFECT | B8: 0.06 | C8: BAND | D8: ComboStep | E8: PERFECT ติดกัน +6% ต่อครั้ง
A9: COMBO Max Steps | B9: 5 | C9: BAND | D9: ComboMax | E9: สูงสุด +30%
A10: FORTISSIMO after combo | B10: 8 | C10: BAND | D10: FortissimoCombo
A11: FORTISSIMO lasts (beats) | B11: 4 | C11: BAND | D11: FortissimoBeats
A12: FORTISSIMO power | B12: 1.3 | C12: BAND | D12: FortissimoPower
A13: IN TUNE : TACET keeps | B13: 0.6 | C13: TACET | D13: InTuneKeep | E13: ตรงเวลา + ขนาดตรงตัวอักษรจริง
A14: COUNTER : TACET keeps | B14: 0.7 | C14: TACET | D14: CounterKeep | E14: PERFECT ตวัดใหญ่ใส่โน้ต f จริง
A15: TACET f note | B15: 2 | C15: TACET | D15: EnemyBoostPower | E15: โน้ต f ของ TACET แรง ×2
A16: TACET p note | B16: 0.5 | C16: TACET | D16: EnemyEasePower | E16: โน้ต p แรง ×0.5
A17: TACET'S BLOW (breath per point) | B17: 0.95 | C17: BREATH | D17: BlowPerPower | E17: บีตที่ TACET ชนะ วงเสียลม 0.95 ต่อแต้มที่แพ้
A18: Rest : breath back | B18: 12 | C18: BREATH | D18: RestRecover | E18: บีตเงียบ ไม่ตวัดหรือตวัดเล็ก = พัก
A20: Special Notes (TREMOLO · FERMATA · SPARK · FINALE)
A21: Parameter | B21: NORMAL | C21: MAESTRO | D21: Code | E21: Notes
A22: TREMOLO length (beats) | B22: 2 | C22: 2 | D22: TremoloBeats | E22: Elite/บอสจบทุกรอบด้วยโน้ตรัว
A23: TREMOLO : TACET power | B23: 1.5 | C23: 1.5 | D23: TremoloEnemy
A24: TREMOLO : base share (no shakes) | B24: 0.4 | C24: 0.4 | D24: TremoloBase
A25: TREMOLO : per shake | B25: 0.15 | C25: 0.15 | D25: TremoloStep
A26: TREMOLO : shakes counted (max) | B26: 10 | C26: 10 | D26: TremoloMost
A27: TREMOLO : shakes for PERFECT | B27: 5 | C27: 6 | D27: TremoloPerfect / Maestro…
A28: TREMOLO : shakes for GOOD | B28: 3 | C28: 4 | D28: TremoloGood / Maestro…
A29: FERMATA length (beats) | B29: 2 | C29: 2 | D29: FermataBeats | E29: ศัตรูธรรมดาจบรอบด้วยโน้ตค้าง (ชั้น 2+)
A30: FERMATA : TACET power | B30: 1.3 | C30: 1.3 | D30: FermataEnemy
A31: FERMATA : let go at once | B31: 0.6 | C31: 0.6 | D31: FermataBase
A32: FERMATA : added over the hold | B32: 0.8 | C32: 0.8 | D32: FermataHold | E32: ค้างจนจบ = ×1.4
A33: FERMATA : still speed (px/s) | B33: 260 | C33: 260 | D33: FermataStill | E33: ไม้ขยับไม่เกินนี้ถือว่านิ่ง
A34: SPARK pairs in round 1 / 2 / 3 | B34: 2 / 3 / 4 | C34: 2 / 3 / 4 | D34: DoubleNotes | E34: โน้ตคู่
A35: SPARK : share of its beat | B35: 0.5 | C35: 0.5 | D35: GraceShare
A36: FINALE : extra shards | B36: 25 | C36: 25 | D36: FinaleShards | E36: จบด้วย FINALE ได้ shards เพิ่ม
A38: Conductor Skill Matrix (PASSIVE + SIGNATURE)
A39: SIGNATURE ทำงาน 4 ตวัด หลังเก็บโน้ตครบตาม Recipe (แท็บ Entity Tuning) แล้วกด Space
A40: Skill | B40: Value | C40: Conductor | D40: Code | E40: Notes / Mechanics
A41: BY THE BOOK (passive) | B41: - | C41: THE APPRENTICE | D41: - | E41: GOOD ก็เก็บโน้ตสูตรได้ (คนอื่นต้อง PERFECT)
A42: ABSOLUTE PITCH (signature) | B42: - | C42: THE APPRENTICE | D42: - | E42: 4 ตวัด : ตรงเวลา = ขนาดถูก + IN TUNE
...

Sheet Difficulty Curve
A1: Difficulty Curve — NORMAL / MAESTRO
A3: Tempo (BPM)
A4: ดวลเร็วขึ้นทุกรอบ และทุกชั้น · ms/beat = 60000 ÷ BPM (เวลาระหว่างบีต)
A5: Mode / Floor | B5: Round 1 | C5: Round 2 | D5: Round 3 | E5: R1 ms/beat | F5: R2 ms/beat | G5: R3 ms/beat | H5: Notes
A6: NORMAL · Floor 1 | B6: 70 | C6: 76 | D6: 84 | E6: =60000/B6 | F6: =60000/C6 | G6: =60000/D6 | H6: TempoByFloor
A7: NORMAL · Floor 2 | B7: 80 | C7: 90 | D7: 100 | E7: =60000/B7 | F7: =60000/C7 | G7: =60000/D7 | H7: TempoByFloor
A8: NORMAL · Floor 3 | B8: 88 | C8: 100 | D8: 112 | E8: =60000/B8 | F8: =60000/C8 | G8: =60000/D8 | H8: TempoByFloor
A9: MAESTRO · Floor 1 | B9: 96 | C9: 112 | D9: 128 | E9: =60000/B9 | F9: =60000/C9 | G9: =60000/D9 | H9: MaestroTempo
A10: MAESTRO · Floor 2 | B10: 96 | C10: 112 | D10: 128 | E10: =60000/B10 | F10: =60000/C10 | G10: =60000/D10 | H10: MaestroTempo
A11: MAESTRO · Floor 3 | B11: 96 | C11: 112 | D11: 128 | E11: =60000/B11 | F11: =60000/C11 | G11: =60000/D11 | H11: MaestroTempo
A13: Mode Differences
A14: Parameter | B14: NORMAL | C14: MAESTRO | D14: Notes
A15: Gentle fights (TACET plays only f and p) | B15: 3 | C15: 0 | D15: ดวลแรกๆ ของรัน ไม่มี mf · GENTLE เล่นแค่บีต 1 กับ 3
A16: Rolls (TREMOLO) from floor | B16: 1 | C16: 1 | D16: NORMAL : เฉพาะ Elite/บอสในชั้น 1
A17: Held notes (FERMATA) from floor | B17: 2 | C17: 1 | D17: ศัตรูธรรมดา
A18: Pairs (SPARK) from floor | B18: 2 | C18: 1
A19: PERFECT window (± ms) | B19: 100 | C19: 80
A20: GOOD window (± ms) | B20: 220 | C20: 180
A21: Wrong size keeps | B21: 0.5 | C21: 0.3 | D21: ⚠️ ยังรอผู้ใช้ตัดสิน : NORMAL 50% ทำให้ฟาดใหญ่ทุกโน้ตชนะ 77% ในตัวจำลอง
A22: Shakes for a PERFECT roll | B22: 5 | C22: 6
A23: Floor power F1 | B23: ='Entity Tuning'!$B$41 | C23: ='Entity Tuning'!$B$42 | D23: จากแท็บ Entity Tuning
A24: Floor power F2 | B24: ='Entity Tuning'!$C$41 | C24: ='Entity Tuning'!$C$42
A25: Floor power F3 | B25: ='Entity Tuning'!$D$41 | C25: ='Entity Tuning'!$D$42
A27: Enemy Note Power by Floor (mf note · from Entity Tuning)
A28: โน้ต f = ×2 · p = ×0.5 · ใช้ดูว่าแต่ละชั้นศัตรูแรงขึ้นแค่ไหน
A29: Enemy | B29: NORMAL F1 | C29: NORMAL F2 | D29: NORMAL F3 | E29: MAESTRO F1 | F29: MAESTRO F2 | G29: MAESTRO F3 | H29: Kind
A30: HUSH | B30: ='Entity Tuning'!F47 | C30: ='Entity Tuning'!G47 | D30: ='Entity Tuning'!H47 | E30: ='Entity Tuning'!I47 | F30: ='Entity Tuning'!J47 | G30: ='Entity Tuning'!K47 | H30: ='Entity Tuning'!B47
A31: DEAD AIR | B31: ='Entity Tuning'!F48 | C31: ='Entity Tuning'!G48 | D31: ='Entity Tuning'!H48 | E31: ='Entity Tuning'!I48 | F31: ='Entity Tuning'!J48 | G31: ='Entity Tuning'!K48 | H31: ='Entity Tuning'!B48
A32: THE LULL | B32: ='Entity Tuning'!F49 | C32: ='Entity Tuning'!G49 | D32: ='Entity Tuning'!H49 | E32: ='Entity Tuning'!I49 | F32: ='Entity Tuning'!J49 | G32: ='Entity Tuning'!K49 | H32: ='Entity Tuning'!B49
A33: STATIC | B33: ='Entity Tuning'!F50 | C33: ='Entity Tuning'!G50 | D33: ='Entity Tuning'!H50 | E33: ='Entity Tuning'!I50 | F33: ='Entity Tuning'!J50 | G33: ='Entity Tuning'!K50 | H33: ='Entity Tuning'!B50
A34: THE MUTE CHOIR | B34: ='Entity Tuning'!F51 | C34: ='Entity Tuning'!G51 | D34: ='Entity Tuning'!H51 | E34: ='Entity Tuning'!I51 | F34: ='Entity Tuning'!J51 | G34: ='Entity Tuning'!K51 | H34: ='Entity Tuning'!B51
A35: WHITE NOISE | B35: ='Entity Tuning'!F52 | C35: ='Entity Tuning'!G52 | D35: ='Entity Tuning'!H52 | E35: ='Entity Tuning'!I52 | F35: ='Entity Tuning'!J52 | G35: ='Entity Tuning'!K52 | H35: ='Entity Tuning'!B52
A36: REQUIEM | B36: ='Entity Tuning'!F53 | C36: ='Entity Tuning'!G53 | D36: ='Entity Tuning'!H53 | E36: ='Entity Tuning'!I53 | F36: ='Entity Tuning'!J53 | G36: ='Entity Tuning'!K53 | H36: ='Entity Tuning'!B53
A37: THE NAMELESS MASTER | B37: ='Entity Tuning'!F54 | C37: ='Entity Tuning'!G54 | D37: ='Entity Tuning'!H54 | E37: ='Entity Tuning'!I54 | F37: ='Entity Tuning'!J54 | G37: ='Entity Tuning'!K54 | H37: ='Entity Tuning'!B54
A38: THE DEVIL'S STRING | B38: ='Entity Tuning'!F55 | C38: ='Entity Tuning'!G55 | D38: ='Entity Tuning'!H55 | E38: ='Entity Tuning'!I55 | F38: ='Entity Tuning'!J55 | G38: ='Entity Tuning'!K55 | H38: ='Entity Tuning'!B55

Sheet Economy
A1: Economy — Shards · Shop · Rest · Rewards
A3: Rewards
A4: Parameter | B4: Value | C4: Code | D4: Notes
A5: Shards : normal win | B5: 20 | C5: ShardsNormal
A6: Shards : elite win | B6: 40 | C6: ShardsElite
A7: Shards : boss win | B7: 80 | C7: ShardsBoss
A8: Shards per PERFECT | B8: 1 | C8: ShardsPerPerfect
A9: Motif offered after normal win | B9: 0.6 | C9: MotifChanceNormal | D9: Elite/บอสได้เสนอทุกครั้ง
A10: Motif choices | B10: 3 | C10: MotifChoices | D10: เลือก 1 จาก 3
A11: Skip motif pays | B11: 15 | C11: SkipMotifShards
A12: Elite drops a musician | B12: 0.5 | C12: EliteRecruitChance
A14: Motif Prices (by rarity)
A15: Rarity | B15: Price | C15: Code | D15: Notes
A16: 1 · COMMON | B16: 45 | C16: MotifPrice[1]
A17: 2 · RARE | B17: 70 | C17: MotifPrice[2]
A18: 3 · TREASURED | B18: 100 | C18: MotifPrice[3]
A20: Shop
A21: Parameter | B21: Value | C21: Code | D21: Notes
A22: Extra seat : first price | B22: 55 | C22: SeatPriceBase
A23: Extra seat : each next adds | B23: 25 | C23: SeatPriceStep
A24: Extra seat : 2nd price | B24: =B22+B23 | C24: (คำนวณ)
A25: Extra seat : 3rd price | B25: =B22+2*B23 | C25: (คำนวณ)
A26: Seats buyable per floor | B26: 2 | C26: SeatsPerFloor | D26: สูงสุด 9 ที่บนเวที
A27: Tuning price | B27: 30 | C27: TuningPrice
A28: Tuning breath back | B28: 0.4 | C28: TuningRecover | D28: คืนลม 40% ของสูงสุด
A29: Hire a musician | B29: 80 | C29: HirePrice | D29: คนจากยุคนี้
A31: Rest
A32: Parameter | B32: Value | C32: Code | D32: Notes
A33: BREATHE : breath back (free) | B33: 0.4 | C33: BreatheRecover | D33: คืนลม 40%
A34: DEEP REST : price | B34: 35 | C34: DeepRestPrice | D34: คืนลมเต็ม
A35: REHEARSE : +1 power, times per musician | B35: 3 | C35: RehearseMax
A37: Event Checks
A38: Parameter | B38: Value | C38: Code | D38: Notes
A39: Chance per point of power | B39: 0.05 | C39: CheckPerPower | D39: โอกาส = ฐานของตัวเลือก + พลัง × 5%
A40: Asked family bonus | B40: 0.25 | C40: CheckFamilyBonus

Sheet Sim Results
A1: Simulation Results (ตัวจำลอง ไม่ใช่คนเล่นจริง)
A3: Run Win Rate — 29 ก.ย. ก้อน 8 (หลังใส่เพลง 7 เพลง, APPRENTICE)
A4: จาก `--shots simulate` / `audit` ใน Core/DebugShots.cs · ความแม่นตาม BPM เป็นสมมติฐาน · ผลแกว่ง ±5–8% ระหว่างรัน
A5: Player Type | B5: NORMAL | C5: MAESTRO | D5: Notes
A6: Flawless | B6: 1 | C6: 0.99
A7: Skilled | B7: 0.92 | C7: 0.64
A8: Average | B8: 0.62 | C8: 0.14
A9: Newcomer | B9: 0.04 | C9: 0
A10: Big stroke on every note | B10: 0.77 | C10: 0.25 | D10: ฟาดใหญ่ทุกโน้ตโดยไม่อ่านตัวอักษร
A12: Conductor Win Rate — 29 ก.ย. ก้อน 6 (NORMAL, ก่อนใส่เพลงของ Elite/บอส)
A13: ตัวเลขชุดเก่ากว่าแถวบน ใช้เทียบระหว่างคอนดักเตอร์เท่านั้น
A14: Conductor | B14: Skilled | C14: Average | D14: Notes
A15: THE APPRENTICE | B15: 0.96 | C15: 0.67
A16: THE METRONOME | B16: 0.97 | C16: 0.74
A17: THE INFERNO | B17: 0.98 | C17: 0.67
A18: THE UNHEARING | B18: 0.98 | C18: 0.58
A19: THE FOLK LEADER | B19: 0.96 | C19: 0.48

Sheet About
A1: TACET 4'33 — Balance Sheet
A2: ทำเมื่อ | B2: 9 ต.ค. 2026 · branch Alpha6 (รอบ 15) · รูปแบบตามตัวอย่างของอาจารย์ (Battlefleet_Balance.xlsx : Game States / Entity Tuning / Skill Damage) + แท็บเพิ่ม Difficulty Curve / Economy / Sim Results
A3: ที่มาของตัวเลข | B3: อ่านจากโค้ดจริง : Data/BattleRules.cs (ตัวเลขบาลานซ์ทุกตัว) · Data/Conductor.cs · Data/Musician.cs · Data/Enemy.cs · Data/Motif.cs · Core/GestureReader.cs · คอลัมน์ Code บอกชื่อตัวแปร
A4: แก้ตัวเลขที่ไหน | B4: ไฟล์นี้ไม่เชื่อมกับเกม แก้ในชีตแล้วเกมไม่เปลี่ยน → แก้ที่ Data/BattleRules.cs (หรือไฟล์ Data ตามคอลัมน์ Code) แล้วอัปเดตชีตตาม
A5: ช่องที่เป็นสูตร | B5: Max Breath · Power × · แรงโน้ตศัตรูต่อชั้น · Push to Win · ms/beat · ราคาที่นั่ง · ราคา Motif · Beats in a Full Duel · ค่าเฉลี่ยพลังนักดนตรี — เปลี่ยนค่าต้นทางแล้วคำนวณใหม่เอง
A6: การปัดเศษแรงศัตรู | B6: เกมใช้ C# Math.Round (ค่า .5 ปัดไปหาเลขคู่) สูตรในชีตจึงเป็น ROUND(x,0) − (MOD(x,2)=0.5) ให้ตรงกับเกม เช่น MAESTRO ชั้น 1 ของ MUTE CHOIR = 10 (ไม่ใช่ 11)
A7: Sim Results | B7: มาจากตัวจำลองในเกม (Core/DebugShots.cs) ยังไม่มีเพลย์เทสกับคนจริงของรอบ 15
A8: Alpha 7 | B8: แท็บ Turn Battle / Turn Enemies / Turn Conductors / Turn Sim = การต่อสู้แบบผลัดตา (branch Alpha7, 19 ต.ค.) สร้างจากโค้ดด้วยสคริปต์ ค่าในแท็บอื่นเป็นของดวลเดิม (Alpha6) ที่ยังอยู่ในโค้ดตอนปิด TurnBattleOn

Sheet Turn Battle
A1: Section | B1: Code (BattleRules) | C1: Value | D1: Notes
A2: Turn Battle On | B2: TurnBattleOn | C2: true
A3: Life Word | B3: LifeWord | C3: TurnBattleOn ? "LIFE" : "BREATH"
A4: Life Word | B4: LifeWordLower | C4: TurnBattleOn ? "life" : "breath"
A5: Life and Speed of the band | B5: TurnHp | C5: { 30, 26, 36 }
A6: Life and Speed of the band | B6: TurnSpeed | C6: { 5, 7, 3 }
A7: Life and Speed of TACET | B7: TurnEnemyHp | C7: { 50, 120, 250 }
A8: Life and Speed of TACET | B8: TurnEnemySpeed | C8: { 4, 4, 4 }
A9: Attack | B9: TurnAttackPerPower | C9: 2
A10: Attack | B10: TurnPerfect | C10: 1.3 | D10: right way, right size, on time
A11: Attack | B11: TurnGood | C11: 1 | D11: right way, right size, a little off time
A12: Attack | B12: TurnWrongSize | C12: 0.7 | D12: on time but the wrong size
A13: Attack | B13: TurnMiss | C13: 0.4 | D13: the wrong way, too early, too late or no swipe
A14: ONE BAR | B14: TurnAttackScale | C14: 1 | D14: ATTACK : no swipe, it always hits at this
A15: ONE BAR | B15: TurnAttackOffBeat | C15: 10 | D15: ATTACK : the OFF-BEAT it adds
A16: ONE BAR | B16: TurnStartBand | C16: 2 | D16: musicians on the field when a fight starts (FULL STAGE in the ARCHIVE adds 1)
A17: ONE BAR | B17: TurnFieldMost | C17: 6 | D17: musicians on the field at most, the called ones too
A18: ONE BAR | B18: TurnCallCost | C18: 3 | D18: CALL : BREATH to bring one in from the BENCH, one per bar (NORMAL)
A19: ONE BAR | B19: MaestroTurnCallCost | C19: 5 | D19: MAESTRO
A20: ONE BAR | B20: TurnCallCostStep | C20: 1 | D20: the second call of a fight and every one after costs this much more
A21: ONE BAR | B21: TurnCutInSpeed | C21: 5 | D21: CUT IN : an enemy this fast plays in the middle of the bar
... A28: PACKS | B28: TurnShardsPerEscort | C28: 6 | D28: shards for each enemy beyond the first
A29: Floor Scale | B29: TurnFloorLife | C29: { 1, 1.3, 1.6 }
A30: Floor Scale | B30: TurnFloorDamage | C30: { 1, 1.2, 1.4 }
A31: Enemy Traits in the turn battle | B31: TurnFillsGapsScale | C31: 1.5 | D31: DEAD AIR : a missed note
A32: Enemy Traits in the turn battle | B32: TurnLullHeal | C32: 12 | D32: THE LULL : life back on its humming turn
A33: Enemy Traits in the turn battle | B33: TurnLullEvery | C33: 3 | D33: every this many turns
A34: Enemy Traits in the turn battle | B34: TurnFastGap | C34: 0.7 | D34: REQUIEM : the gap between notes below half life
A35: Enemy Traits in the turn battle | B35: TurnBargainSteal | C35: 1 | D35: THE DEVIL'S STRING : breath taken by each attack
A36: ONE BAR enemies | B36: TurnRoomToneKeep | C36: 0.7 | D36: ROOM TONE : the share of the band's damage the OTHER enemies take while it stands
A37: ONE BAR enemies | B37: TurnFeltHandCall | C37: 1 | D37: THE DAMPER : a CALL costs this much more while it stands (2 left the sim's STRONG player at 23 percent against it)
A38: ONE BAR enemies | B38: TurnTwiceFirst | C38: 1 | D38: STUTTER : cuts in after this many of the band's moves
A39: ONE BAR enemies | B39: TurnTwiceSecond | C39: 3 | D39: and again after this many
A40: PRACTICE | B40: TurnPracticeHp | C40: 160
A41: PRACTICE | B41: TurnPracticeSpeed | C41: 4
A42: PRACTICE | B42: TurnPracticePower | C42: 2 | D42: each note hits this x TurnNoteDamage (4 life)
A43: Enemy Attack | B43: TurnNotesMin | C43: { 1, 2, 3 } | D43: ELITE and BOSS
A44: Enemy Attack | B44: TurnNotesMax | C44: { 2, 3, 4 }
A45: Enemy Attack | B45: TurnSmallNotesMin | C45: { 1, 1, 2 } | D45: ordinary enemies
A46: Enemy Attack | B46: TurnSmallNotesMax | C46: { 2, 2, 2 }
...

Sheet Turn Enemies
A1: Enemy | B1: Kind | C1: Life (floor 1) | D1: Speed | E1: Note power (avg Pattern) | F1: Phrases | G1: Trait (from floor) | H1: Trait in the turn battle | I1: CUT IN (speed 5 or more)
A2: HUSH | B2: Normal | C2: 50 | D2: 4 | E2: 4 | F2: Dp Up, Lp Rp Dp | G2: ECHO FADES (2) | H2: Each note that gets through adds 1 DISSONANCE.
A3: DEAD AIR | B3: Normal | C3: 50 | D3: 4 | E3: 4 | F3: Lmf Rmf, Dmf Dmf Umf | G3: FILLS THE GAPS (2) | H3: A note you miss hits 50 percent harder.
A4: THE LULL | B4: Normal | C4: 60 | D4: 2 | E4: 4 | F4: Dp Dp, Up Dp Up | G4: LULLABY (2) | H4: Every third turn it hums instead of attacking and gets back 12 life.
A5: STATIC | B5: Normal | C5: 45 | D5: 5 | E5: 4 | F5: Lf Rp, Umf Df Lp | G5: FALSE NOTES (2) | H5: One note of each attack shows the wrong size. | I5: yes
A6: THE MUTE CHOIR | B6: Elite | C6: 120 | D6: 4 | E6: 5 | F6: Df Df Uf, Lmf Rmf Lmf Rmf | G6: SILENT MOUTHS (1) | H6: A note that gets through takes the target's skills away for a turn.
A7: WHITE NOISE | B7: Elite | C7: 110 | D7: 6 | E7: 5 | F7: Lp Rp Lp Rp, Up Dp Up Dp | G7: NO REST (1) | H7: One note more in every attack, and parrying it gives no BREATH. | I7: yes
A8: REQUIEM | B8: Boss | C8: 250 | D8: 5 | E8: 6 | F8: Df Lmf Rmf Uf, Lf Rf Lf Rf | G8: UNFINISHED (1) | H8: Below half life it swaps left and right and plays faster. | I8: yes
A9: THE NAMELESS MASTER | B9: Boss | C9: 230 | D9: 4 | E9: 4 | F9: Dmf Umf Lmf, Rf Lf Dp Up | G9: ANSWER BETTER (1) | H9: It answers with the notes of the last skill your band played.
A10: THE DEVIL'S STRING | B10: Boss | C10: 260 | D10: 6 | E10: 8 | F10: Rf Rf Lf, Uf Df Uf Df | G10: THE BARGAIN (1) | H10: Each of its attacks steals 1 BREATH. | I10: yes
A11: ROOM TONE | B11: Normal | C11: 45 | D11: 2 | E11: 4 | F11: Dp, Up Dp | G11: HOLDS THE ROOM (2) | H11: While it stands, the other enemies take 30 percent less.
A12: THE CUE | B12: Normal | C12: 55 | D12: 5 | E12: 4 | F12: Rmf Lmf, Uf | G12: ON CUE (2) | H12: It always strikes the musician who was CALLED in last. | I12: yes
A13: THE DAMPER | B13: Normal | C13: 42 | D13: 3 | E13: 4 | F13: Dmf Dp, Lmf Rmf | G13: FELT HAND (2) | H13: While it stands, a CALL costs 1 more BREATH.
A14: STUTTER | B14: Normal | C14: 36 | D14: 7 | E14: 4 | F14: Lp, Rp, Up | G14: TWICE A BAR (2) | H14: It cuts in twice a bar, after the 1st and the 3rd move, one note each time. | I14: yes
A15: THE ROUND | B15: Elite | C15: 115 | D15: 4 | E15: 5 | F15: Df Dmf Df, Lmf Rmf Lf Rf | G15: FIRST IN LINE (1) | H15: It always strikes the musician who plays first in the bar.

Sheet Turn Conductors
A1: Conductor | B1: Based on | C1: Kit | D1: PASSIVE | E1: What it does | F1: SIGNATURE | G1: What it does
A2: THE METRONOME | B2: J. S. BACH | C2: Bach | D2: LOCKED TEMPO | E2: Any size you swing is the right size. You only keep time. | F2: FUGUE | G2: The 4/4 shape : every musician's next move plays twice. Better strokes, louder echo.
A3: THE UNHEARING | B3: L. V. BEETHOVEN | C3: Beethoven | D3: THE CLOSER THE LOUDER | E3: The less life the band has left, the harder it hits, up to 50 percent. | F3: LIGHTNING | G3: The 4/4 shape : strikes every enemy and throws it OFF-BEAT. Better strokes, bigger strike.
A4: THE SHADOWLESS | B4: W. A. MOZART | C4: Mozart | D4: PRODIGY | E4: 3 PERFECTs in a row give 1 BREATH back. | F4: FEATHER | G4: The 4/4 shape : two free ATTACKs at the end of the bar per stroke that lands.
A5: THE HEARTLESS | B5: NICCOLO PAGANINI | C5: Paganini | D5: BORROWED BREATH | E5: A skill short of BREATH can still be played. Each missing BREATH costs 3 life. | F5: CAPRICE | G5: The 4/4 shape : for two turns per stroke that lands, a MISS is GOOD and a GOOD is PERFECT. Then every musician pays 10 percent of their life.
A6: THE KING'S BATON | B6: J. B. LULLY | C6: Lully | D6: STEADY HAND | E6: Blocking TACET's notes is easier : both windows are wider. | F6: THE SUN | G6: The 4/4 shape : life back for every musician, and DISSONANCE and MUTE are gone. Better strokes, more life.
A7: THE UNSIGNED | B7: FANNY MENDELSSOHN | C7: Fanny | D7: TWO VOICES | E7: The voices take turns, one musician each : FANNY hits 25 percent harder, FELIX heals 50 percent more. | F7: DUET | G7: The 4/4 shape : FANNY strikes every enemy while FELIX heals every musician.

Sheet Turn Sim
A1: turnsim.txt (--shots turnsim, Core/DebugShots.TurnSim.cs)
A2: TACET TURN BATTLE BALANCE, ONE BAR (200 fights per cell, 300 runs per player)
A3: Players : timing spread FLAWLESS 0 / EXPERT 0.08 / STRONG 0.12 / AVERAGE 0.2 / NEWCOMER 0.3 seconds
A5: FIGHTS at full life (4 musicians, 2 on the field) : WIN PERCENT / BARS / LIFE LOST PERCENT / CALLS
A6: FLAWLESS FLOOR 1 EARLY 100% 2.0b 0% 1.8c LATE 100% 2.9b 0% 2.0c ELITE 100% 3.0b 0% 1.9c BOSS 100% 4.9b 0% 2.0c
A7: FLAWLESS FLOOR 2 EARLY 100% 3.0b 0% 2.0c LATE 100% 3.2b 0% 2.0c ELITE 100% 3.9b 0% 2.0c BOSS 100% 5.7b 0% 2.0c
A8: FLAWLESS FLOOR 3 EARLY 100% 3.9b 0% 2.0c LATE 100% 4.2b 0% 2.0c ELITE 100% 4.4b 0% 2.0c BOSS 100% 6.9b 0% 2.0c
A9: EXPERT FLOOR 1 EARLY 100% 2.0b 2% 1.5c LATE 100% 3.0b 5% 2.0c ELITE 100% 3.4b 5% 2.0c BOSS 100% 5.1b 11% 2.0c
A10: EXPERT FLOOR 2 EARLY 100% 3.3b 8% 2.0c LATE 100% 3.5b 11% 2.0c ELITE 100% 4.1b 14% 2.0c BOSS 100% 6.3b 19% 2.0c
A11: EXPERT FLOOR 3 EARLY 100% 4.1b 13% 2.0c LATE 100% 4.8b 15% 2.0c ELITE 100% 5.2b 19% 2.0c BOSS 99% 7.7b 31% 2.0c
A12: STRONG FLOOR 1 EARLY 100% 2.2b 6% 1.4c LATE 100% 3.1b 11% 2.0c ELITE 100% 3.7b 12% 1.9c BOSS 100% 5.6b 24% 2.0c
A13: STRONG FLOOR 2 EARLY 100% 3.6b 17% 2.0c LATE 100% 4.1b 25% 2.0c ELITE 100% 4.7b 28% 2.0c BOSS 87% 7.4b 50% 2.0c
... A58: THE UNSIGNED 50% / 0%
